<robot
  name="rm_description">
  <link
    name="base_link">
    <inertial>
      <origin
        xyz="-0.000109373565465087 -0.000540506855878586 0.0596939182288847"
        rpy="0 0 0" />
      <mass
        value="0.272558169881355" />
      <inertia
        ixx="0.000784258212393038"
        ixy="6.29959493193312E-06"
        ixz="-1.76459744676658E-05"
        iyy="0.000779239170957765"
        iyz="-8.63136641574899E-07"
        izz="0.000487751716575412" />
    </inertial>
    <visual>
      <origin
        xyz="0 0 0"
        rpy="0 0 0" />
      <geometry>
        <mesh
          filename="package://rm_description/meshes/base_link.STL" />
      </geometry>
      <material
        name="">
        <color
          rgba="1 1 1 1" />
      </material>
    </visual>
    <collision>
      <origin
        xyz="0 0 0"
        rpy="0 0 0" />
      <geometry>
        <mesh
          filename="package://rm_description/meshes/base_link.STL" />
      </geometry>
    </collision>
  </link>
  <link
    name="link1">
    <inertial>
      <origin
        xyz="1.03803520729029E-06 -0.0103990426169562 0.0743349525008567"
        rpy="0 0 0" />
      <mass
        value="0.215133901253052" />
      <inertia
        ixx="0.000738411845651515"
        ixy="4.9343358529989E-09"
        ixz="-7.40107563498747E-09"
        iyy="0.000752630863743101"
        iyz="8.29235260567527E-05"
        izz="0.000345883612905226" />
    </inertial>
    <visual>
      <origin
        xyz="0 0 0"
        rpy="0 0 0" />
      <geometry>
        <mesh
          filename="package://rm_description/meshes/link1.STL" />
      </geometry>
      <material
        name="">
        <color
          rgba="1 1 1 1" />
      </material>
    </visual>
    <collision>
      <origin
        xyz="0 0 0"
        rpy="0 0 0" />
      <geometry>
        <mesh
          filename="package://rm_description/meshes/link1.STL" />
      </geometry>
    </collision>
  </link>
  <joint
    name="joint1"
    type="revolute">
    <origin
      xyz="0 0 0.1327"
      rpy="3.4694E-18 2.4378E-13 -3.1416" />
    <parent
      link="base_link" />
    <child
      link="link1" />
    <axis
      xyz="0 0 1" />
    <limit
      lower="-3.05"
      upper="3.05"
      effort="0"
      velocity="0" />
  </joint>
  <link
    name="link2">
    <inertial>
      <origin
        xyz="0.125617616072843 0.00357568268785996 0.0132826613843138"
        rpy="0 0 0" />
      <mass
        value="0.283929826592835" />
      <inertia
        ixx="0.000411191576002741"
        ixy="-6.53114733016414E-05"
        ixz="-0.00050447716245518"
        iyy="0.00271431366843969"
        iyz="-1.42823833900128E-05"
        izz="0.00264679251140964" />
    </inertial>
    <visual>
      <origin
        xyz="0 0 0"
        rpy="0 0 0" />
      <geometry>
        <mesh
          filename="package://rm_description/meshes/link2.STL" />
      </geometry>
      <material
        name="">
        <color
          rgba="1 1 1 1" />
      </material>
    </visual>
    <collision>
      <origin
        xyz="0 0 0"
        rpy="0 0 0" />
      <geometry>
        <mesh
          filename="package://rm_description/meshes/link2.STL" />
      </geometry>
    </collision>
  </link>
  <joint
    name="joint2"
    type="revolute">
    <origin
      xyz="0 0.01355 0.1193"
      rpy="-3.1343 -1.5708 -1.5562" />
    <parent
      link="link1" />
    <child
      link="link2" />
    <axis
      xyz="0 0 1" />
    <limit
      lower="-2"
      upper="2"
      effort="0"
      velocity="0" />
  </joint>
  <link
    name="link3">
    <inertial>
      <origin
        xyz="-2.62322173649743E-07 -0.0531866163941078 0.00185294381389689"
        rpy="0 0 0" />
      <mass
        value="0.111073907035842" />
      <inertia
        ixx="0.00033047679713022"
        ixy="1.31716200247089E-09"
        ixz="-4.56890740152993E-10"
        iyy="0.000104053844810698"
        iyz="7.71086571035923E-05"
        izz="0.000321094433322306" />
    </inertial>
    <visual>
      <origin
        xyz="0 0 0"
        rpy="0 0 0" />
      <geometry>
        <mesh
          filename="package://rm_description/meshes/link3.STL" />
      </geometry>
      <material
        name="">
        <color
          rgba="1 1 1 1" />
      </material>
    </visual>
    <collision>
      <origin
        xyz="0 0 0"
        rpy="0 0 0" />
      <geometry>
        <mesh
          filename="package://rm_description/meshes/link3.STL" />
      </geometry>
    </collision>
  </link>
  <joint
    name="joint3"
    type="revolute">
    <origin
      xyz="0.2464 0.007 0.0015"
      rpy="-1.7347E-18 -5.5511E-17 1.5708" />
    <parent
      link="link2" />
    <child
      link="link3" />
    <axis
      xyz="0 0 1" />
    <limit
      lower="-2"
      upper="2"
      effort="0"
      velocity="0" />
  </joint>
  <link
    name="link4">
    <inertial>
      <origin
        xyz="-1.89389405602647E-07 0.0125575326860273 0.0583180851477226"
        rpy="0 0 0" />
      <mass
        value="0.0997648971440612" />
      <inertia
        ixx="0.000191682166188519"
        ixy="1.01339370300543E-09"
        ixz="8.67961926602371E-10"
        iyy="0.000177823631535319"
        iyz="-2.99893599167277E-05"
        izz="9.86902095260074E-05" />
    </inertial>
    <visual>
      <origin
        xyz="0 0 0"
        rpy="0 0 0" />
      <geometry>
        <mesh
          filename="package://rm_description/meshes/link4.STL" />
      </geometry>
      <material
        name="">
        <color
          rgba="1 1 1 1" />
      </material>
    </visual>
    <collision>
      <origin
        xyz="0 0 0"
        rpy="0 0 0" />
      <geometry>
        <mesh
          filename="package://rm_description/meshes/link4.STL" />
      </geometry>
    </collision>
  </link>
  <joint
    name="joint4"
    type="revolute">
    <origin
      xyz="0 -0.1304 0.01745"
      rpy="1.5708 -5.5511E-17 1.7347E-18" />
    <parent
      link="link3" />
    <child
      link="link4" />
    <axis
      xyz="0 0 1" />
    <limit
      lower="-3.05"
      upper="3.05"
      effort="0"
      velocity="0" />
  </joint>
  <link
    name="link5">
    <inertial>
      <origin
        xyz="-2.3157236272997E-07 -0.0507443613513162 0.00177089430075761"
        rpy="0 0 0" />
      <mass
        value="0.0957664896685306" />
      <inertia
        ixx="0.000228496433142371"
        ixy="-5.7261396795782E-09"
        ixz="1.54923483788963E-09"
        iyy="8.10391564318016E-05"
        iyz="5.22320419179966E-05"
        izz="0.00021939996729031" />
    </inertial>
    <visual>
      <origin
        xyz="0 0 0"
        rpy="0 0 0" />
      <geometry>
        <mesh
          filename="package://rm_description/meshes/link5.STL" />
      </geometry>
      <material
        name="">
        <color
          rgba="1 1 1 1" />
      </material>
    </visual>
    <collision>
      <origin
        xyz="0 0 0"
        rpy="0 0 0" />
      <geometry>
        <mesh
          filename="package://rm_description/meshes/link5.STL" />
      </geometry>
    </collision>
  </link>
  <joint
    name="joint5"
    type="revolute">
    <origin
      xyz="0 -0.0142 0.0872"
      rpy="-1.5708 1.7347E-18 5.5511E-17" />
    <parent
      link="link4" />
    <child
      link="link5" />
    <axis
      xyz="0 0 1" />
    <limit
      lower="-2"
      upper="2"
      effort="0"
      velocity="0" />
  </joint>
  <link
    name="link6">
    <inertial>
      <origin
        xyz="-0.000457792901041587 8.72837963215023E-05 -0.012860781989493"
        rpy="0 0 0" />
      <mass
        value="0.0454115343474848" />
      <inertia
        ixx="1.92594513199535E-05"
        ixy="3.54327832160295E-08"
        ixz="1.83353519645419E-08"
        iyy="1.84993535241476E-05"
        iyz="-4.30694743278975E-08"
        izz="3.03164748974575E-05" />
    </inertial>
    <visual>
      <origin
        xyz="0 0 0"
        rpy="0 0 0" />
      <geometry>
        <mesh
          filename="package://rm_description/meshes/link6.STL" />
      </geometry>
      <material
        name="">
        <color
          rgba="1 1 1 1" />
      </material>
    </visual>
    <collision>
      <origin
        xyz="0 0 0"
        rpy="0 0 0" />
      <geometry>
        <mesh
          filename="package://rm_description/meshes/link6.STL" />
      </geometry>
    </collision>
  </link>
  <joint
    name="joint6"
    type="revolute">
    <origin
      xyz="0 -0.1471 0.0146"
      rpy="1.5708 -7.8126E-13 -2.4378E-13" />
    <parent
      link="link5" />
    <child
      link="link6" />
    <axis
      xyz="0 0 1" />
    <limit
      lower="-6.28"
      upper="6.28"
      effort="0"
      velocity="0" />
  </joint>
  <link
    name="hand">
    <inertial>
      <origin
        xyz="3.68536599532066E-06 1.38476910288565E-05 -0.0635543718731382"
        rpy="0 0 0" />
      <mass
        value="0.082055165002889" />
      <inertia
        ixx="7.75460020380294E-05"
        ixy="5.95576719120136E-09"
        ixz="3.18736283185322E-09"
        iyy="6.74927016477138E-05"
        iyz="1.52185606100357E-08"
        izz="2.37834843803893E-05" />
    </inertial>
    <visual>
      <origin
        xyz="0 0 0"
        rpy="0 0 0" />
      <geometry>
        <mesh
          filename="package://rm_description/meshes/hand.STL" />
      </geometry>
      <material
        name="">
        <color
          rgba="1 1 1 1" />
      </material>
    </visual>
    <collision>
      <origin
        xyz="0 0 0"
        rpy="0 0 0" />
      <geometry>
        <mesh
          filename="package://rm_description/meshes/hand.STL" />
      </geometry>
    </collision>
  </link>
  <joint
    name="hand_joint"
    type="fixed">
    <origin
      xyz="0 0 0.1"
      rpy="-1.7347E-18 2.4378E-13 -7.8121E-13" />
    <parent
      link="link6" />
    <child
      link="hand" />
    <axis
      xyz="0 0 0" />
  </joint>
  <link
    name="left_gripper">
    <inertial>
      <origin
        xyz="1.18772258694833E-09 -0.0385742590736997 0.013272877911639"
        rpy="0 0 0" />
      <mass
        value="0.0109461974636394" />
      <inertia
        ixx="5.17437903546281E-06"
        ixy="1.75385234924992E-13"
        ixz="-1.35251319790756E-13"
        iyy="5.12956285880332E-06"
        iyz="2.7509204694877E-07"
        izz="6.91852711687168E-07" />
    </inertial>
    <visual>
      <origin
        xyz="0 0 0"
        rpy="0 0 0" />
      <geometry>
        <mesh
          filename="package://rm_description/meshes/left_gripper.STL" />
      </geometry>
      <material
        name="">
        <color
          rgba="1 1 1 1" />
      </material>
    </visual>
    <collision>
      <origin
        xyz="0 0 0"
        rpy="0 0 0" />
      <geometry>
        <mesh
          filename="package://rm_description/meshes/left_gripper.STL" />
      </geometry>
    </collision>
  </link>
  <joint
    name="left_gripper_joint"
    type="fixed">
    <origin
      xyz="0 0 0"
      rpy="-3.4694E-18 1.7347E-18 5.5511E-17" />
    <parent
      link="hand" />
    <child
      link="left_gripper" />
    <axis
      xyz="0 0 0" />
    <limit
      lower="-0.4"
      upper="0"
      effort="0"
      velocity="0" />
  </joint>
  <link
    name="right_gripper">
    <inertial>
      <origin
        xyz="7.21624926480757E-10 0.0385742637249681 0.0132728826799009"
        rpy="0 0 0" />
      <mass
        value="0.010946201175683" />
      <inertia
        ixx="5.17438056395939E-06"
        ixy="-4.42075998881688E-14"
        ixz="-9.3204048470003E-14"
        iyy="5.12956362052274E-06"
        iyz="-2.75092652786187E-07"
        izz="6.91853570150896E-07" />
    </inertial>
    <visual>
      <origin
        xyz="0 0 0"
        rpy="0 0 0" />
      <geometry>
        <mesh
          filename="package://rm_description/meshes/right_gripper.STL" />
      </geometry>
      <material
        name="">
        <color
          rgba="1 1 1 1" />
      </material>
    </visual>
    <collision>
      <origin
        xyz="0 0 0"
        rpy="0 0 0" />
      <geometry>
        <mesh
          filename="package://rm_description/meshes/right_gripper.STL" />
      </geometry>
    </collision>
  </link>
  <joint
    name="right_gripper_joint"
    type="fixed">
    <origin
      xyz="0 0 0"
      rpy="-3.4694E-18 1.7347E-18 5.5511E-17" />
    <parent
      link="hand" />
    <child
      link="right_gripper" />
    <axis
      xyz="0 0 0" />
    <limit
      lower="0"
      upper="0.4"
      effort="0"
      velocity="0" />
  </joint>
</robot>
